2019-09-04 21:03:25,384 ERROR: Exception on / [GET] [in C:\xampp\htdocs\microblog\venv\lib\site-packages\flask\app.py:1891]
Traceback (most recent call last):
  File "C:\xampp\htdocs\microblog\venv\lib\site-packages\flask\app.py", line 2446, in wsgi_app
    response = self.full_dispatch_request()
  File "C:\xampp\htdocs\microblog\venv\lib\site-packages\flask\app.py", line 1951, in full_dispatch_request
    rv = self.handle_user_exception(e)
  File "C:\xampp\htdocs\microblog\venv\lib\site-packages\flask\app.py", line 1820, in handle_user_exception
    reraise(exc_type, exc_value, tb)
  File "C:\xampp\htdocs\microblog\venv\lib\site-packages\flask\_compat.py", line 39, in reraise
    raise value
  File "C:\xampp\htdocs\microblog\venv\lib\site-packages\flask\app.py", line 1949, in full_dispatch_request
    rv = self.dispatch_request()
  File "C:\xampp\htdocs\microblog\venv\lib\site-packages\flask\app.py", line 1935, in dispatch_request
    return self.view_functions[rule.endpoint](**req.view_args)
  File "C:\xampp\htdocs\microblog\venv\lib\site-packages\flask_login\utils.py", line 261, in decorated_view
    return func(*args, **kwargs)
  File "C:\xampp\htdocs\microblog\app\routes.py", line 21, in index
    return render_template('index.html',title='Home',posts=posts,form=form)
  File "C:\xampp\htdocs\microblog\venv\lib\site-packages\flask\templating.py", line 140, in render_template
    ctx.app,
  File "C:\xampp\htdocs\microblog\venv\lib\site-packages\flask\templating.py", line 120, in _render
    rv = template.render(context)
  File "C:\xampp\htdocs\microblog\venv\lib\site-packages\jinja2\asyncsupport.py", line 76, in render
    return original_render(self, *args, **kwargs)
  File "C:\xampp\htdocs\microblog\venv\lib\site-packages\jinja2\environment.py", line 1008, in render
    return self.environment.handle_exception(exc_info, True)
  File "C:\xampp\htdocs\microblog\venv\lib\site-packages\jinja2\environment.py", line 780, in handle_exception
    reraise(exc_type, exc_value, tb)
  File "C:\xampp\htdocs\microblog\venv\lib\site-packages\jinja2\_compat.py", line 37, in reraise
    raise value.with_traceback(tb)
  File "C:\xampp\htdocs\microblog\app\templates\index.html", line 1, in top-level template code
    {% extends "base.html" %}
  File "C:\xampp\htdocs\microblog\app\templates\base.html", line 11, in top-level template code
    <a href="{{ url_for('explore') }}">Explore</a>
  File "C:\xampp\htdocs\microblog\venv\lib\site-packages\flask\helpers.py", line 370, in url_for
    return appctx.app.handle_url_build_error(error, endpoint, values)
  File "C:\xampp\htdocs\microblog\venv\lib\site-packages\flask\app.py", line 2215, in handle_url_build_error
    reraise(exc_type, exc_value, tb)
  File "C:\xampp\htdocs\microblog\venv\lib\site-packages\flask\_compat.py", line 39, in reraise
    raise value
  File "C:\xampp\htdocs\microblog\venv\lib\site-packages\flask\helpers.py", line 358, in url_for
    endpoint, values, method=method, force_external=external
  File "C:\xampp\htdocs\microblog\venv\lib\site-packages\werkzeug\routing.py", line 2020, in build
    raise BuildError(endpoint, values, method, self)
werkzeug.routing.BuildError: Could not build url for endpoint 'explore'. Did you mean 'edit_profile' instead?
2019-09-04 21:04:44,653 INFO: Microblog startup [in C:\xampp\htdocs\microblog\app\__init__.py:45]
2019-09-04 21:04:47,004 ERROR: Exception on / [GET] [in C:\xampp\htdocs\microblog\venv\lib\site-packages\flask\app.py:1891]
Traceback (most recent call last):
  File "C:\xampp\htdocs\microblog\venv\lib\site-packages\flask\app.py", line 2446, in wsgi_app
    response = self.full_dispatch_request()
  File "C:\xampp\htdocs\microblog\venv\lib\site-packages\flask\app.py", line 1951, in full_dispatch_request
    rv = self.handle_user_exception(e)
  File "C:\xampp\htdocs\microblog\venv\lib\site-packages\flask\app.py", line 1820, in handle_user_exception
    reraise(exc_type, exc_value, tb)
  File "C:\xampp\htdocs\microblog\venv\lib\site-packages\flask\_compat.py", line 39, in reraise
    raise value
  File "C:\xampp\htdocs\microblog\venv\lib\site-packages\flask\app.py", line 1949, in full_dispatch_request
    rv = self.dispatch_request()
  File "C:\xampp\htdocs\microblog\venv\lib\site-packages\flask\app.py", line 1935, in dispatch_request
    return self.view_functions[rule.endpoint](**req.view_args)
  File "C:\xampp\htdocs\microblog\venv\lib\site-packages\flask_login\utils.py", line 261, in decorated_view
    return func(*args, **kwargs)
  File "C:\xampp\htdocs\microblog\app\routes.py", line 21, in index
    return render_template('index.html',title='Home',posts=posts,form=form)
  File "C:\xampp\htdocs\microblog\venv\lib\site-packages\flask\templating.py", line 140, in render_template
    ctx.app,
  File "C:\xampp\htdocs\microblog\venv\lib\site-packages\flask\templating.py", line 120, in _render
    rv = template.render(context)
  File "C:\xampp\htdocs\microblog\venv\lib\site-packages\jinja2\asyncsupport.py", line 76, in render
    return original_render(self, *args, **kwargs)
  File "C:\xampp\htdocs\microblog\venv\lib\site-packages\jinja2\environment.py", line 1008, in render
    return self.environment.handle_exception(exc_info, True)
  File "C:\xampp\htdocs\microblog\venv\lib\site-packages\jinja2\environment.py", line 780, in handle_exception
    reraise(exc_type, exc_value, tb)
  File "C:\xampp\htdocs\microblog\venv\lib\site-packages\jinja2\_compat.py", line 37, in reraise
    raise value.with_traceback(tb)
  File "C:\xampp\htdocs\microblog\app\templates\index.html", line 1, in top-level template code
    {% extends "base.html" %}
  File "C:\xampp\htdocs\microblog\app\templates\base.html", line 11, in top-level template code
    <a href="{{ url_for('explore') }}">Explore</a>
  File "C:\xampp\htdocs\microblog\venv\lib\site-packages\flask\helpers.py", line 370, in url_for
    return appctx.app.handle_url_build_error(error, endpoint, values)
  File "C:\xampp\htdocs\microblog\venv\lib\site-packages\flask\app.py", line 2215, in handle_url_build_error
    reraise(exc_type, exc_value, tb)
  File "C:\xampp\htdocs\microblog\venv\lib\site-packages\flask\_compat.py", line 39, in reraise
    raise value
  File "C:\xampp\htdocs\microblog\venv\lib\site-packages\flask\helpers.py", line 358, in url_for
    endpoint, values, method=method, force_external=external
  File "C:\xampp\htdocs\microblog\venv\lib\site-packages\werkzeug\routing.py", line 2020, in build
    raise BuildError(endpoint, values, method, self)
werkzeug.routing.BuildError: Could not build url for endpoint 'explore'. Did you mean 'edit_profile' instead?
2019-09-04 21:08:56,514 INFO: Microblog startup [in C:\xampp\htdocs\microblog\app\__init__.py:45]
2019-09-06 18:32:24,887 INFO: Microblog startup [in C:\xampp\htdocs\microblog\app\__init__.py:45]
2019-09-06 18:43:25,825 INFO: Microblog startup [in C:\xampp\htdocs\microblog\app\__init__.py:45]
2019-09-06 18:44:01,083 INFO: Microblog startup [in C:\xampp\htdocs\microblog\app\__init__.py:45]
2019-09-06 18:49:17,075 INFO: Microblog startup [in C:\xampp\htdocs\microblog\app\__init__.py:45]
2019-09-06 18:53:10,476 INFO: Microblog startup [in C:\xampp\htdocs\microblog\app\__init__.py:45]
2019-09-06 18:53:12,428 ERROR: Exception on / [GET] [in C:\xampp\htdocs\microblog\venv\lib\site-packages\flask\app.py:1891]
Traceback (most recent call last):
  File "C:\xampp\htdocs\microblog\venv\lib\site-packages\flask\app.py", line 2446, in wsgi_app
    response = self.full_dispatch_request()
  File "C:\xampp\htdocs\microblog\venv\lib\site-packages\flask\app.py", line 1951, in full_dispatch_request
    rv = self.handle_user_exception(e)
  File "C:\xampp\htdocs\microblog\venv\lib\site-packages\flask\app.py", line 1820, in handle_user_exception
    reraise(exc_type, exc_value, tb)
  File "C:\xampp\htdocs\microblog\venv\lib\site-packages\flask\_compat.py", line 39, in reraise
    raise value
  File "C:\xampp\htdocs\microblog\venv\lib\site-packages\flask\app.py", line 1949, in full_dispatch_request
    rv = self.dispatch_request()
  File "C:\xampp\htdocs\microblog\venv\lib\site-packages\flask\app.py", line 1935, in dispatch_request
    return self.view_functions[rule.endpoint](**req.view_args)
  File "C:\xampp\htdocs\microblog\venv\lib\site-packages\flask_login\utils.py", line 261, in decorated_view
    return func(*args, **kwargs)
  File "C:\xampp\htdocs\microblog\app\routes.py", line 24, in index
    posts=posts.items,next_url=next_url,prev_url=prev_url)
NameError: name 'next_url' is not defined
2019-09-06 19:02:09,864 INFO: Microblog startup [in C:\xampp\htdocs\microblog\app\__init__.py:45]
